Workbook
Name _xlcn.WorksheetConnection_MicrobialInfoA3Z43: 'Microbial Info'!$A$3:$AD$43

Sheet ID Search
B5: Information Sheet
B6: Culture Collection of Applied Microbiology Laboratory
B7: School of Arts & Sciences, University of San Carlos - Talamban Campus
C10: {=INDEX('Microbial Info'!$D$4:$D$43, MATCH('ID Search'!D12, 'Microbial Info'!A4:A42, 0))} -> Bacillus cereus strain DZ102
C11: Only input the code in the highlighted cell below (Yellow) to update information. Do not alter the formula.
C12: Code: | D12: CBN1 | G12: Classification: | H12: {=INDEX('Microbial Info'!$C$4:$C$43, MATCH(D12,'Microbial Info'!A4:A42,0))} -> Bacteria
C13: Locale: | D13: {=INDEX(Resources!$C$3:$C$42, MATCH('ID Search'!D12,Resources!$A$3:$A$42,0))} -> Bantayan Island, Cebu | G13: Project Fund: | H13: {=INDEX(Resources!$B$3:$B$42, MATCH(D12,Resources!$A$3:$A$42,0))} -> NRCP Sediment Project
C14: Source: | D14: {=INDEX(Resources!$D$3:$D$42,MATCH('ID Search'!D12,Resources!$A$3:$A$42,0))} -> Mangrove Sediment | G14: Date Accessed:
C16: Summary of Information
C17: 16s rRNA Gene Sequencing | F17: Substrate Assimilation (API)
C18: FASTA File: | D18: {=INDEX('Microbial Info'!$G$4:$G$43, MATCH($D$12,'Microbial Info'!$A$4:$A$43,0))} | F18: ONPG: | G18: {=INDEX('Microbial Info'!$AJ$4:$AJ$43, MATCH($D$12,'Microbial Info'!$A$4:$A$43,0))} | H18: GLU: | I18: {=INDEX('Microbial Info'!$AV$4:$AV$43, MATCH($D$12,'Microbial Info'!$A$4:$A$43,0))}
C19: Accession No: | D19: {=INDEX('Microbial Info'!$F$4:$F$43, MATCH($D$12,'Microbial Info'!$A$4:$A$43,0))} -> HM015629 | F19: ADH: | G19: {=INDEX('Microbial Info'!$AL$4:$AL$43, MATCH($D$12,'Microbial Info'!$A$4:$A$43,0))} | H19: MAN: | I19: {=INDEX('Microbial Info'!$AW$4:$AW$43, MATCH($D$12,'Microbial Info'!$A$4:$A$43,0))}
C20: Similarity %: | D20: {=INDEX('Microbial Info'!E4:E43, MATCH($D$12,'Microbial Info'!A4:A42,0))} -> 0.9516 | F20: LDC: | G20: {=INDEX('Microbial Info'!$AM$4:$AM$43, MATCH($D$12,'Microbial Info'!$A$4:$A$43,0))} | H20: INO: | I20: {=INDEX('Microbial Info'!$AX$4:$AX$43, MATCH($D$12,'Microbial Info'!$A$4:$A$43,0))}
C21: Biochemical Characteristics | F21: ODC: | G21: {=INDEX('Microbial Info'!$AN$4:$AN$43, MATCH($D$12,'Microbial Info'!$A$4:$A$43,0))} | H21: SOR: | I21: {=INDEX('Microbial Info'!$AY$4:$AY$43, MATCH($D$12,'Microbial Info'!$A$4:$A$43,0))}
C22: Catalase: | D22: {=INDEX('Microbial Info'!$Y$4:$Y$43, MATCH($D$12,'Microbial Info'!$A$4:$A$43,0))} -> Positive | F22: CIT: | G22: {=INDEX('Microbial Info'!$AO$4:$AO$43, MATCH($D$12,'Microbial Info'!$A$4:$A$43,0))} | H22: RHA: | I22: {=INDEX('Microbial Info'!$AZ$4:$AZ$43, MATCH($D$12,'Microbial Info'!$A$4:$A$43,0))}
C23: Hemolysis: | D23: {=INDEX('Microbial Info'!$AA$4:$AA$43,MATCH($D$12,'Microbial Info'!A4:A43,0))} -> Beta-hemolysis | F23: H2S: | G23: {=INDEX('Microbial Info'!$AP$4:$AP$43, MATCH($D$12,'Microbial Info'!$A$4:$A$43,0))} | H23: SAC: | I23: {=INDEX('Microbial Info'!$AZ$4:$AZ$43, MATCH($D$12,'Microbial Info'!$A$4:$A$43,0))}
C24: Oxidase: | D24: {=INDEX('Microbial Info'!$Z$4:$Z$43, MATCH($D$12,'Microbial Info'!$A$4:$A$43,0))} -> Negative | F24: URE: | G24: {=INDEX('Microbial Info'!$AQ$4:$AQ$43, MATCH($D$12,'Microbial Info'!$A$4:$A$43,0))} | H24: MEL: | I24: {=INDEX('Microbial Info'!$BB$4:$BB$43, MATCH($D$12,'Microbial Info'!$A$4:$A$43,0))}
F25: TDA: | G25: {=INDEX('Microbial Info'!$AR$4:$AR$43, MATCH($D$12,'Microbial Info'!$A$4:$A$43,0))} | H25: AMY: | I25: {=INDEX('Microbial Info'!$BC$4:$BC$43, MATCH($D$12,'Microbial Info'!$A$4:$A$43,0))}
F26: IND: | G26: {=INDEX('Microbial Info'!$AS$4:$AS$43, MATCH($D$12,'Microbial Info'!$A$4:$A$43,0))} | H26: ARA: | I26: {=INDEX('Microbial Info'!$BD$4:$BD$43, MATCH($D$12,'Microbial Info'!$A$4:$A$43,0))}
F27: VP: | G27: {=INDEX('Microbial Info'!$AT$4:$AT$43, MATCH($D$12,'Microbial Info'!$A$4:$A$43,0))} | H27: NO2: | I27: {=INDEX('Microbial Info'!$BE$4:$BE$43, MATCH($D$12,'Microbial Info'!$A$4:$A$43,0))}
F28: GEL: | G28: {=INDEX('Microbial Info'!$AU$4:$AU$43, MATCH($D$12,'Microbial Info'!$A$4:$A$43,0))} | H28: Result:
C29: Cell and Colony Morphology
C30: {=INDEX('Microbial Info'!U4:U43, MATCH('ID Search'!D12,'Microbial Info'!A4:A42,0))} -> Colonies of Bacillus cereus strain DZ102 grown on LB Agar for 24-48 h are approximately in diameter. Cell shape is rod and is gram-positive. Pigmentation is white and are opaque. Colonies are mucoid and are circular in form with entire margin. They have convex elevation. When manipulated with a needle, the colonies are butyrous.
C34: Maintenance and Use
C35: Growth Media: | D35: {=INDEX(Resources!E3:E42, MATCH($D$12,'Microbial Info'!A4:A42,0))}
C36: Special Reqs:
C37: Activity: | D37: {=INDEX('Microbial Info'!H4:H43, MATCH($D$12,'Microbial Info'!A4:A42,0))}
C38: Protein and Peptides Detected
C39: Retention Time | D39: Compound | E39: Mobile Phase A | F39: Mobile Phase B
C51: Other Tests Performed
C52: Name of Test/s | F52: Result | G52: Notes
C53: 1
C54: 2
C55: 3
C56: 4
C57: 5
C58: 6
C59: 7
C60: 8
C61: 9
...

Sheet Microbial Info
D2: Molecular Information | I2: Cell and Colony Morphology | V2: Biochemical and Physiological Characteristics | AJ2: Analytical Profile Index
A3: Code | B3: Project | C3: Classification | D3: 16s rRNA | E3: Similarity | F3: Accession Number | G3: Primer | H3: Pathogenecity | I3: Shape | J3: Cell Size | K3: Colony Size | L3: Pigmentation | M3: Form | N3: Elevation | O3: Margin | P3: Colony Surface | Q3: Opacity | R3: Texture | S3: Spore Formation | T3: Mycelium Formation | U3: Description | V3: Gram's Stain | W3: Spore Stain | X3: Motility | Y3: Catalase | Z3: Oxidase | AA3: Hemolysis | AB3: Sulfide Production | AC3: Indole Test | AD3: Growth Media | AE3: Optimal pH | AF3: Optimal Temperature | AG3: Optimal Salinity | AH3: Optimal Growth Rate | AI3: Assigned Identity | AJ3: API Type | AK3: 2KG 2-Ketogluconate | AL3: 5KG 5-Ketogluconate | AM3: ADH Arginine DiHydrolase | AN3: ADO D-Adonitol | AO3: AMD Starch | AP3: AMY Amygdaline | AQ3: ARA L-arabinose | AR3: ARB Arbutine | AS3: CEL D-Celobiose | AT3: CIT Citrate Utilization | AU3: DARA D-Arabinose | AV3: DARL D-Arabitol | AW3: DFUC D-Fucose | AX3: DUL Dulcitol | AY3: DXYL D-Xylose | AZ3: ERY Erytrol | BA3: ESC Esculin | BB3: FRU Fructose | BC3: GAL Galactose | BD3: GEL Gelatinase | BE3: GEN Gentiobiose | BF3: GLU Glucose | BG3: GLY Glycerol | BH3: GLYG Glycogen | BI3: GNT Potasium gluconate | BJ3: H2S production | BK3: IND Indole production | BL3: INO Inozitol | BM3: INU Inuline | BN3: LAC D-Lactose | BO3: LARA L-Arabinose | BP3: LARL L-Arabitol | BQ3: LDC Lysine DeCarboxylase | BR3: LFUC L-Fucose | BS3: LXYL L-Xylose | BT3: LYX D-Lyxose | BU3: MAL D-Maltose | BV3: MAN Manitol | BW3: MDG Metil-a-D-Glucopyranoside | BX3: MDM Metil-a-D-Manopyranoside | BY3: MDX Metil-β-D-Xylopyranoside | BZ3: MEL D-Melibiose | CA3: MLZ D-Melezitose | CB3: MNE Manose | CC3: NAG N-Acetyl-glucosamine Amygdaline | CD3: NO2 production | CE3: ODC Ornithine DeCarboxylase | CF3: ONPG ß-galactosidase (Ortho NitroPhenyl-ßD Galactopyranosidase) | CG3: RAF D-Rafinose | CH3: RHA Rhamnose | CI3: RIB Ribose | CJ3: SAC D-Sucrose | CK3: SAL Salicin | CL3: SBE Sorbose | CM3: SOR Sorbitol | CN3: TAG D-Tagatose | CO3: TDA Tryptophane DeAminase | CP3: TRE D-Trehalose | CQ3: TUR D-Turanose | CR3: URE UREase | CS3: VP Acetoin production (Voges Proskauer) | CT3: XLT Xylitol
A4: ABN2 | B4: NRCP | C4: Bacteria | I4: cocci | L4: off-white | M4: punctiform | N4: convex | O4: undulate | P4: smooth | Q4: translucent | R4: butyrous | U4: =CONCATENATE("Colonies of"," ",'Microbial Info'!$D4, " ","grown on LB Agar for 24-48 h are approximately", " ",K4," ","in diameter."," ","Cell shape is"," ",'Microbial Info'!$I4," ","and is"," ",'Microbial Info'!$V4,"."," ","Pigmentation is"," ",'Microbial Info'!$L4," ","and are"," ", 'Microbial Info'!$Q4,"."," ","Colonies are"," ",'Microbial Info'!$P4," ","and are"," ",'Microbial Info'!$M4," ","in form with"," ",'Microbial Info'!$O4," ","margin."," ","They have"," ",'Microbial Info'!$N4," ","elevation."," ","When manipulated with a needle, the colonies are"," ",'Microbial Info'!$R4,".") -> Colonies of grown on LB Agar for 24-48 h are approximately in diameter. Cell shape is cocci and is gram-negative. Pigmentation is off-white and are translucent. Colonies are smooth and are punctiform in form with undulate margin. They have convex elevation. When manipulated with a needle, the colonies are butyrous. | V4: gram-negative | W4: Positive | X4: Negative | Y4: Positive | AA4: Beta-hemolysis | AB4: Negative | AC4: Negative
A5: ABN8 | B5: NRCP | I5: cocci | V5: gram-positive
A6: BBN22 | B6: NRCP | I6: cocci | W6: Negative
A7: BBN23 | B7: NRCP | I7: cocci | W7: Negative
A8: BBN24 | B8: NRCP | I8: rods | L8: yellow | M8: irregular | N8: convex | O8: undulate | P8: smooth | Q8: opaque | R8: viscous | U8: =CONCATENATE("Colonies of"," ",'Microbial Info'!$D8, " ","grown on LB Agar for 24-48 h are approximately", " ",K8," ","in diameter."," ","Cell shape is"," ",'Microbial Info'!$I8," ","and is"," ",'Microbial Info'!$V8,"."," ","Pigmentation is"," ",'Microbial Info'!$L8," ","and are"," ", 'Microbial Info'!$Q8,"."," ","Colonies are"," ",'Microbial Info'!$P8," ","and are"," ",'Microbial Info'!$M8," ","in form with"," ",'Microbial Info'!$O8," ","margin."," ","They have"," ",'Microbial Info'!$N8," ","elevation."," ","When manipulated with a needle, the colonies are"," ",'Microbial Info'!$R8,".") -> Colonies of grown on LB Agar for 24-48 h are approximately in diameter. Cell shape is rods and is gram-positive. Pigmentation is yellow and are opaque. Colonies are smooth and are irregular in form with undulate margin. They have convex elevation. When manipulated with a needle, the colonies are viscous. | V8: gram-positive | W8: Positive
A9: BBN25 | B9: NRCP | I9: cocci | W9: Negative
A10: BBN26 | B10: NRCP | I10: rods | V10: gram-positive | W10: Positive
A11: BBN27 | B11: NRCP | C11: Bacteria | I11: cocci | L11: Beige to light yellow | M11: circular | N11: raised | O11: entire | P11: smooth | Q11: opaque | R11: viscous | U11: =CONCATENATE("Colonies of"," ",'Microbial Info'!$D11, " ","grown on LB Agar for 24-48 h are approximately", " ",K11," ","in diameter."," ","Cell shape is"," ",'Microbial Info'!$I11," ","and is"," ",'Microbial Info'!$V11,"."," ","Pigmentation is"," ",'Microbial Info'!$L11," ","and are"," ", 'Microbial Info'!$Q11,"."," ","Colonies are"," ",'Microbial Info'!$P11," ","and are"," ",'Microbial Info'!$M11," ","in form with"," ",'Microbial Info'!$O11," ","margin."," ","They have"," ",'Microbial Info'!$N11," ","elevation."," ","When manipulated with a needle, the colonies are"," ",'Microbial Info'!$R11,".") -> Colonies of grown on LB Agar for 24-48 h are approximately in diameter. Cell shape is cocci and is gram-negative. Pigmentation is Beige to light yellow and are opaque. Colonies are smooth and are circular in form with entire margin. They have raised elevation. When manipulated with a needle, the colonies are viscous. | V11: gram-negative | W11: Negative | X11: Negative | Y11: Positive | AA11: Alpha-hemolysis | AB11: Negative | AC11: Negative
A12: BBN32 | B12: NRCP | I12: cocci | W12: Negative
A13: BBN42 | B13: NRCP | C13: Bacteria | I13: rods | L13: light pink | M13: irregular | N13: flat | O13: entire | P13: mucoid and wrinkly | Q13: opaque | R13: viscous | U13: =CONCATENATE("Colonies of"," ",'Microbial Info'!$D13, " ","grown on LB Agar for 24-48 h are approximately", " ",K13," ","in diameter."," ","Cell shape is"," ",'Microbial Info'!$I13," ","and is"," ",'Microbial Info'!$V13,"."," ","Pigmentation is"," ",'Microbial Info'!$L13," ","and are"," ", 'Microbial Info'!$Q13,"."," ","Colonies are"," ",'Microbial Info'!$P13," ","and are"," ",'Microbial Info'!$M13," ","in form with"," ",'Microbial Info'!$O13," ","margin."," ","They have"," ",'Microbial Info'!$N13," ","elevation."," ","When manipulated with a needle, the colonies are"," ",'Microbial Info'!$R13,".") -> Colonies of grown on LB Agar for 24-48 h are approximately in diameter. Cell shape is rods and is gram-positive. Pigmentation is light pink and are opaque. Colonies are mucoid and wrinkly and are irregular in form with entire margin. They have flat elevation. When manipulated with a needle, the colonies are viscous. | V13: gram-positive | W13: Positive | X13: Negative | Y13: Positive | AA13: Alpha-hemolysis | AB13: Negative | AC13: Negative
A14: BBN44 | B14: NRCP | I14: rod | V14: gram-positive
A15: CBN1 | B15: NRCP | C15: Bacteria | D15: Bacillus cereus strain DZ102 | E15: 0.9516 | F15: HM015629 | I15: rod | L15: white | M15: circular | N15: convex | O15: entire | P15: mucoid | Q15: opaque | R15: butyrous | U15: =CONCATENATE("Colonies of"," ",'Microbial Info'!$D15, " ","grown on LB Agar for 24-48 h are approximately", " ",K15," ","in diameter."," ","Cell shape is"," ",'Microbial Info'!$I15," ","and is"," ",'Microbial Info'!$V15,"."," ","Pigmentation is"," ",'Microbial Info'!$L15," ","and are"," ", 'Microbial Info'!$Q15,"."," ","Colonies are"," ",'Microbial Info'!$P15," ","and are"," ",'Microbial Info'!$M15," ","in form with"," ",'Microbial Info'!$O15," ","margin."," ","They have"," ",'Microbial Info'!$N15," ","elevation."," ","When manipulated with a needle, the colonies are"," ",'Microbial Info'!$R15,".") -> Colonies of Bacillus cereus strain DZ102 grown on LB Agar for 24-48 h are approximately in diameter. Cell shape is rod and is gram-positive. Pigmentation is white and are opaque. Colonies are mucoid and are circular in form with entire margin. They have convex elevation. When manipulated with a needle, the colonies are butyrous. | V15: gram-positive | W15: Positive | X15: Negative | Y15: Positive | Z15: Negative | AA15: Beta-hemolysis | AB15: Negative | AC15: Negative
A16: CBN10 | B16: NRCP | I16: cocci | W16: Negative
A17: CBN12 | B17: NRCP | I17: coccobacilli | W17: Positive
A18: CBN13 | B18: NRCP | C18: Bacteria | I18: coccobacilli | L18: white | M18: irregular | N18: flat | O18: undulate | P18: dull and matte | Q18: translucent | R18: butyrous | U18: =CONCATENATE("Colonies of"," ",'Microbial Info'!$D18, " ","grown on LB Agar for 24-48 h are approximately", " ",K18," ","in diameter."," ","Cell shape is"," ",'Microbial Info'!$I18," ","and is"," ",'Microbial Info'!$V18,"."," ","Pigmentation is"," ",'Microbial Info'!$L18," ","and are"," ", 'Microbial Info'!$Q18,"."," ","Colonies are"," ",'Microbial Info'!$P18," ","and are"," ",'Microbial Info'!$M18," ","in form with"," ",'Microbial Info'!$O18," ","margin."," ","They have"," ",'Microbial Info'!$N18," ","elevation."," ","When manipulated with a needle, the colonies are"," ",'Microbial Info'!$R18,".") -> Colonies of grown on LB Agar for 24-48 h are approximately in diameter. Cell shape is coccobacilli and is gram-positive. Pigmentation is white and are translucent. Colonies are dull and matte and are irregular in form with undulate margin. They have flat elevation. When manipulated with a needle, the colonies are butyrous. | V18: gram-positive | W18: Positive | X18: Positive | Y18: Positive | AA18: Alpha-hemolysis | AB18: Negative | AC18: Negative
A19: CBN16 | B19: NRCP | C19: Bacteria (Pathogen) | I19: coccobacilli | V19: gram-positive | W19: Negative | X19: Positive | Y19: Positive | AA19: Alpha-hemolysis | AB19: Negative | AC19: Negative
A20: CBN19 | B20: NRCP | I20: cocci | W20: Negative
A21: CBN5 | B21: NRCP | E21: =RIGHT(D21,6) | I21: cocci | W21: Negative
A22: CBN7 | B22: NRCP | E22: =RIGHT(D22,6) | I22: coccobacilli | W22: Positive
A23: MCL001 | B23: MicroLab Strains | C23: Bacteria (Pathogen) | D23: Aeromonas hydrophila | E23: Reference Strain | I23: rod
A24: MCL002 | B24: MicroLab Strains | C24: Fungi (Pathogen) | D24: Aspergillus niger | E24: Reference Strain | I24: flask
A25: MCL003 | B25: MicroLab Strains | C25: Fungi (Pathogen) | D25: Aureobasidium pullulans (Code: V) | E25: Reference Strain | I25: Variable
A26: MCL004 | B26: MicroLab Strains | C26: Bacteria (Pathogen) | D26: Bacillus cereus | E26: Reference Strain | I26: rod
A27: MCL005 | B27: MicroLab Strains | C27: Bacteria | D27: Bacillus clausii | E27: Reference Strain | I27: rod
A28: MCL006 | B28: MicroLab Strains | C28: Bacteria | D28: Bacillus subtilis | E28: Reference Strain | I28: rod
A29: MCL007 | B29: MicroLab Strains | C29: Bacteria | D29: Bacillus thuringiensis | E29: Reference Strain | I29: rod
A30: MCL008 | B30: MicroLab Strains | C30: Fungi (Pathogen) | D30: Candida albicans | E30: Reference Strain | I30: coccobacilli
A31: MCL009 | B31: MicroLab Strains | C31: Fungi (Pathogen) | D31: Candida bombicola | E31: Reference Strain | I31: coccobacilli
A32: MCL0010 | B32: MicroLab Strains | C32: Fungi (Pathogen) | D32: Candida tropicalis | E32: Reference Strain | I32: coccobacilli
A33: MCL0011 | B33: MicroLab Strains | C33: Bacteria | D33: Chromobacterium violaceum | E33: Reference Strain | I33: coccobacilli
A34: MCL0012 | B34: MicroLab Strains | C34: Fungi (Pathogen) | D34: Colletotrichum capsici | E34: Reference Strain
A35: MCL0013 | B35: MicroLab Strains | C35: Bacteria (Pathogen) | D35: Corynebacterium glutamicum | E35: Reference Strain | I35: rod
A36: MCL0014 | B36: MicroLab Strains | C36: Bacteria (Pathogen) | D36: Escherichia coli | E36: Reference Strain | I36: rod
A37: MCL0015 | B37: MicroLab Strains | C37: Bacteria (Pathogen) | D37: Escherichia coli OP50 | E37: Reference Strain | I37: rod
A38: MCL0016 | B38: MicroLab Strains | C38: Fungi (Pathogen) | D38: Fusarium oxysporum | E38: Reference Strain
A39: MCL0017 | B39: MicroLab Strains | C39: Bacteria (Pathogen) | D39: Klebsiella pneumoniae | E39: Reference Strain | I39: rod
A40: MCL0018 | B40: MicroLab Strains | C40: Bacteria | D40: Lactobacillus delbruckii | E40: Reference Strain | I40: rod
A41: MCL0019 | B41: MicroLab Strains | C41: Bacteria (Pathogen) | D41: Methicilin-resistant Staphylococcus aureus | E41: Reference Strain | I41: cocci
...

Sheet Resources
A2: Code | B2: Culture Collection Fund Source | C2: Locale | D2: Source | E2: Growth Media | F2: Special Requirement/s | G2: Stock Culture Type | H2: Stock Medium
A3: ='Microbial Info'!A4 -> ABN2 | B3: NRCP Sediment Project | C3: Bantayan Island, Cebu | D3: Mangrove Sediment
A4: ='Microbial Info'!A5 -> ABN8 | B4: NRCP Sediment Project | C4: Bantayan Island, Cebu | D4: Mangrove Sediment
A5: ='Microbial Info'!A6 -> BBN22 | B5: NRCP Sediment Project | C5: Bantayan Island, Cebu | D5: Mangrove Sediment
A6: ='Microbial Info'!A7 -> BBN23 | B6: NRCP Sediment Project | C6: Bantayan Island, Cebu | D6: Mangrove Sediment
A7: ='Microbial Info'!A8 -> BBN24 | B7: NRCP Sediment Project | C7: Bantayan Island, Cebu | D7: Mangrove Sediment
A8: ='Microbial Info'!A9 -> BBN25 | B8: NRCP Sediment Project | C8: Bantayan Island, Cebu | D8: Mangrove Sediment
A9: ='Microbial Info'!A10 -> BBN26 | B9: NRCP Sediment Project | C9: Bantayan Island, Cebu | D9: Mangrove Sediment
A10: ='Microbial Info'!A11 -> BBN27 | B10: NRCP Sediment Project | C10: Bantayan Island, Cebu | D10: Mangrove Sediment
A11: ='Microbial Info'!A12 -> BBN32 | B11: NRCP Sediment Project | C11: Bantayan Island, Cebu | D11: Mangrove Sediment
A12: ='Microbial Info'!A13 -> BBN42 | B12: NRCP Sediment Project | C12: Bantayan Island, Cebu | D12: Mangrove Sediment
A13: ='Microbial Info'!A14 -> BBN44 | B13: NRCP Sediment Project | C13: Bantayan Island, Cebu | D13: Mangrove Sediment
A14: ='Microbial Info'!A15 -> CBN1 | B14: NRCP Sediment Project | C14: Bantayan Island, Cebu | D14: Mangrove Sediment
... A42: ='Microbial Info'!A43 -> MCL0021 | B42: MicroLab Culture Collection | C42: Lab Collection | D42: Reference Strain

Sheet Bioactivity
D2: Microorganisms Tested
A3: Code | B3: Bioactivity | C3: Assay/Protocol Used | D3: Test Microorganism (1) | E3: Result (1) | F3: Test Microorganism (2) | G3: Result (2) | H3: Test Microorganism (3) | I3: Result (3) | J3: Test Microorganism (4) | K3: Result (4) | L3: Test Microorganism (5) | M3: Result (5)
A4: ='Microbial Info'!A4 -> ABN2 | B4: Antimicrobial | C4: Agar-well Diffusion Method | D4: Staphylococcus aureus | E4: Susceptible
A5: ='Microbial Info'!A5 -> ABN8
A6: ='Microbial Info'!A6 -> BBN22
A7: ='Microbial Info'!A7 -> BBN23
A8: ='Microbial Info'!A8 -> BBN24
A9: ='Microbial Info'!A9 -> BBN25
A10: ='Microbial Info'!A10 -> BBN26
A11: ='Microbial Info'!A11 -> BBN27
A12: ='Microbial Info'!A12 -> BBN32
A13: ='Microbial Info'!A13 -> BBN42
A14: ='Microbial Info'!A14 -> BBN44
A15: ='Microbial Info'!A15 -> CBN1
A16: ='Microbial Info'!A16 -> CBN10
... A43: ='Microbial Info'!A43 -> MCL0021

Sheet Pivot Table
A1: Descriptive Summary of USC Microbial Collection
B4: Row Labels | C4: Count of Gram's Stain
B5: gram-negative | C5: 2
B6: gram-positive | C6: 8
B7: Grand Total | C7: 10

Sheet Sheet1
B2: Email Address | C2: 20102188@usc.edu.ph
B3: IT Dep USC
